Workbook

Sheet  Employee Master Data
A1: Employee ID | B1: Full Name | C1: Gender | D1: Age | E1: Department | F1: Branch | G1: Job Grade | H1: Employment Type | I1: Education Level | J1: Hire Date | K1: Exit Date | L1: Exit Reason | M1: Status | N1: Monthly Salary ($) | O1: Manager ID | P1: Tenure (Years) | Q1: Tenure Band | R1: Hire Year | S1: Exit Year | T1: Education Level Cleaned
A2: EMP-10001 | B2: Jeffery Smith | C2: Male | D2: 39 | E2: Executive Management | F2: Central Hub | G2: Grade 5 – Lead | H2: Contract | I2: Master's Degree | J2: 43672 | K2: 45724 | L2: Resignation | M2: Inactive | N2: 18449.3 | O2: MGR-10048 | P2: 5.6 | Q2: =IF(Table1[[#This Row],[Tenure (Years)]]<1,"< 1 Year", IF(Table1[[#This Row],[Tenure (Years)]]<2,"1–2 Years", IF(Table1[[#This Row],[Tenure (Years)]]<3,"2–3 Years", IF(Table1[[#This Row],[Tenure (Years)]]<5,"3–5 Years", IF(Table1[[#This Row],[Tenure (Years)]]<10,"5–10 Years", "> 10 Years"))))) -> 5–10 Years | R2: =YEAR(Table1[[#This Row],[Hire Date]]) -> 2019 | S2: =YEAR(Table1[[#This Row],[Exit Date]]) -> 2025 | T2: =IF(Table1[[#This Row],[Education Level]]="Master's Degree", "Master's Degree", IF(Table1[[#This Row],[Education Level]]="Bachelor's Degree", "Bachelor's Degree", "Others")) -> Master's Degree
A3: EMP-10002 | B3: Laura Powell | C3: Female | D3: 33 | E3: Sales | F3: Head Office | G3: Grade 2 – Junior | H3: Permanent | I3: Bachelor's Degree | J3: 46033 | M3: Active | N3: 5505.05 | O3: MGR-10302 | P3: 0.3 | Q3: =IF(Table1[[#This Row],[Tenure (Years)]]<1,"< 1 Year", IF(Table1[[#This Row],[Tenure (Years)]]<2,"1–2 Years", IF(Table1[[#This Row],[Tenure (Years)]]<3,"2–3 Years", IF(Table1[[#This Row],[Tenure (Years)]]<5,"3–5 Years", IF(Table1[[#This Row],[Tenure (Years)]]<10,"5–10 Years", "> 10 Years"))))) -> < 1 Year | R3: =YEAR(Table1[[#This Row],[Hire Date]]) -> 2026 | T3: =IF(Table1[[#This Row],[Education Level]]="Master's Degree", "Master's Degree", IF(Table1[[#This Row],[Education Level]]="Bachelor's Degree", "Bachelor's Degree", "Others")) -> Bachelor's Degree
A4: EMP-10003 | B4: Michelle Rodriguez | C4: Female | D4: 40 | E4: IT | F4: Head Office | G4: Grade 5 – Lead | H4: Permanent | I4: Bachelor's Degree | J4: 45960 | M4: Active | N4: 14038.99 | O4: MGR-10053 | P4: 0.5 | Q4: =IF(Table1[[#This Row],[Tenure (Years)]]<1,"< 1 Year", IF(Table1[[#This Row],[Tenure (Years)]]<2,"1–2 Years", IF(Table1[[#This Row],[Tenure (Years)]]<3,"2–3 Years", IF(Table1[[#This Row],[Tenure (Years)]]<5,"3–5 Years", IF(Table1[[#This Row],[Tenure (Years)]]<10,"5–10 Years", "> 10 Years"))))) -> < 1 Year | R4: =YEAR(Table1[[#This Row],[Hire Date]]) -> 2025 | T4: =IF(Table1[[#This Row],[Education Level]]="Master's Degree", "Master's Degree", IF(Table1[[#This Row],[Education Level]]="Bachelor's Degree", "Bachelor's Degree", "Others")) -> Bachelor's Degree
A5: EMP-10004 | B5: Curtis Friedman | C5: Male | D5: 48 | E5: Human Resources | F5: South Region | G5: Grade 3 – Mid-Level | H5: Contract | I5: Master's Degree | J5: 44184 | M5: Active | N5: 7576.94 | O5: MGR-10283 | P5: 5.4 | Q5: =IF(Table1[[#This Row],[Tenure (Years)]]<1,"< 1 Year", IF(Table1[[#This Row],[Tenure (Years)]]<2,"1–2 Years", IF(Table1[[#This Row],[Tenure (Years)]]<3,"2–3 Years", IF(Table1[[#This Row],[Tenure (Years)]]<5,"3–5 Years", IF(Table1[[#This Row],[Tenure (Years)]]<10,"5–10 Years", "> 10 Years"))))) -> 5–10 Years | R5: =YEAR(Table1[[#This Row],[Hire Date]]) -> 2020 | T5: =IF(Table1[[#This Row],[Education Level]]="Master's Degree", "Master's Degree", IF(Table1[[#This Row],[Education Level]]="Bachelor's Degree", "Bachelor's Degree", "Others")) -> Master's Degree
A6: EMP-10005 | B6: Sheena Campbell | C6: Female | D6: 32 | E6: IT | F6: East Region | G6: Grade 5 – Lead | H6: Permanent | I6: Diploma | J6: 45465 | M6: Active | N6: 17711.12 | O6: MGR-10041 | P6: 1.9 | Q6: =IF(Table1[[#This Row],[Tenure (Years)]]<1,"< 1 Year", IF(Table1[[#This Row],[Tenure (Years)]]<2,"1–2 Years", IF(Table1[[#This Row],[Tenure (Years)]]<3,"2–3 Years", IF(Table1[[#This Row],[Tenure (Years)]]<5,"3–5 Years", IF(Table1[[#This Row],[Tenure (Years)]]<10,"5–10 Years", "> 10 Years"))))) -> 1–2 Years | R6: =YEAR(Table1[[#This Row],[Hire Date]]) -> 2024 | T6: =IF(Table1[[#This Row],[Education Level]]="Master's Degree", "Master's Degree", IF(Table1[[#This Row],[Education Level]]="Bachelor's Degree", "Bachelor's Degree", "Others")) -> Others
A7: EMP-10006 | B7: John Rice | C7: Male | D7: 32 | E7: Sales | F7: East Region | G7: Grade 5 – Lead | H7: Permanent | I7: Bachelor's Degree | J7: 44595 | M7: Active | N7: 16280.76 | O7: MGR-10350 | P7: 4.3 | Q7: =IF(Table1[[#This Row],[Tenure (Years)]]<1,"< 1 Year", IF(Table1[[#This Row],[Tenure (Years)]]<2,"1–2 Years", IF(Table1[[#This Row],[Tenure (Years)]]<3,"2–3 Years", IF(Table1[[#This Row],[Tenure (Years)]]<5,"3–5 Years", IF(Table1[[#This Row],[Tenure (Years)]]<10,"5–10 Years", "> 10 Years"))))) -> 3–5 Years | R7: =YEAR(Table1[[#This Row],[Hire Date]]) -> 2022 | T7: =IF(Table1[[#This Row],[Education Level]]="Master's Degree", "Master's Degree", IF(Table1[[#This Row],[Education Level]]="Bachelor's Degree", "Bachelor's Degree", "Others")) -> Bachelor's Degree
A8: EMP-10007 | B8: James Vang | C8: Male | D8: 49 | E8: Executive Management | F8: Central Hub | G8: Grade 5 – Lead | H8: Permanent | I8: Bachelor's Degree | J8: 44103 | M8: Active | N8: 17809.87 | O8: MGR-10286 | P8: 5.6 | Q8: =IF(Table1[[#This Row],[Tenure (Years)]]<1,"< 1 Year", IF(Table1[[#This Row],[Tenure (Years)]]<2,"1–2 Years", IF(Table1[[#This Row],[Tenure (Years)]]<3,"2–3 Years", IF(Table1[[#This Row],[Tenure (Years)]]<5,"3–5 Years", IF(Table1[[#This Row],[Tenure (Years)]]<10,"5–10 Years", "> 10 Years"))))) -> 5–10 Years | R8: =YEAR(Table1[[#This Row],[Hire Date]]) -> 2020 | T8: =IF(Table1[[#This Row],[Education Level]]="Master's Degree", "Master's Degree", IF(Table1[[#This Row],[Education Level]]="Bachelor's Degree", "Bachelor's Degree", "Others")) -> Bachelor's Degree
A9: EMP-10008 | B9: Jade Elliott | C9: Female | D9: 41 | E9: Sales | F9: North Region | G9: Grade 4 – Senior | H9: Contract | I9: Master's Degree | J9: 44039 | K9: 45872 | L9: Dismissal | M9: Inactive | N9: 13292.83 | O9: MGR-10162 | P9: 5 | Q9: =IF(Table1[[#This Row],[Tenure (Years)]]<1,"< 1 Year", IF(Table1[[#This Row],[Tenure (Years)]]<2,"1–2 Years", IF(Table1[[#This Row],[Tenure (Years)]]<3,"2–3 Years", IF(Table1[[#This Row],[Tenure (Years)]]<5,"3–5 Years", IF(Table1[[#This Row],[Tenure (Years)]]<10,"5–10 Years", "> 10 Years"))))) -> 5–10 Years | R9: =YEAR(Table1[[#This Row],[Hire Date]]) -> 2020 | S9: =YEAR(Table1[[#This Row],[Exit Date]]) -> 2025 | T9: =IF(Table1[[#This Row],[Education Level]]="Master's Degree", "Master's Degree", IF(Table1[[#This Row],[Education Level]]="Bachelor's Degree", "Bachelor's Degree", "Others")) -> Master's Degree
A10: EMP-10009 | B10: Nicole White | C10: Female | D10: 30 | E10: Sales | F10: East Region | G10: Grade 4 – Senior | H10: Permanent | I10: Diploma | J10: 44980 | M10: Active | N10: 11280.34 | O10: MGR-10383 | P10: 3.2 | Q10: =IF(Table1[[#This Row],[Tenure (Years)]]<1,"< 1 Year", IF(Table1[[#This Row],[Tenure (Years)]]<2,"1–2 Years", IF(Table1[[#This Row],[Tenure (Years)]]<3,"2–3 Years", IF(Table1[[#This Row],[Tenure (Years)]]<5,"3–5 Years", IF(Table1[[#This Row],[Tenure (Years)]]<10,"5–10 Years", "> 10 Years"))))) -> 3–5 Years | R10: =YEAR(Table1[[#This Row],[Hire Date]]) -> 2023 | T10: =IF(Table1[[#This Row],[Education Level]]="Master's Degree", "Master's Degree", IF(Table1[[#This Row],[Education Level]]="Bachelor's Degree", "Bachelor's Degree", "Others")) -> Others
A11: EMP-10010 | B11: Brett Bowen | C11: Male | D11: 39 | E11: Procurement | F11: Head Office | G11: Grade 3 – Mid-Level | H11: Permanent | I11: Diploma | J11: 43667 | K11: 45934 | L11: Resignation | M11: Inactive | N11: 8250.6 | O11: MGR-10349 | P11: 6.2 | Q11: =IF(Table1[[#This Row],[Tenure (Years)]]<1,"< 1 Year", IF(Table1[[#This Row],[Tenure (Years)]]<2,"1–2 Years", IF(Table1[[#This Row],[Tenure (Years)]]<3,"2–3 Years", IF(Table1[[#This Row],[Tenure (Years)]]<5,"3–5 Years", IF(Table1[[#This Row],[Tenure (Years)]]<10,"5–10 Years", "> 10 Years"))))) -> 5–10 Years | R11: =YEAR(Table1[[#This Row],[Hire Date]]) -> 2019 | S11: =YEAR(Table1[[#This Row],[Exit Date]]) -> 2025 | T11: =IF(Table1[[#This Row],[Education Level]]="Master's Degree", "Master's Degree", IF(Table1[[#This Row],[Education Level]]="Bachelor's Degree", "Bachelor's Degree", "Others")) -> Others
A12: EMP-10011 | B12: Emily Ross | C12: Female | D12: 30 | E12: Marketing | F12: West Region | G12: Grade 4 – Senior | H12: Permanent | I12: Professional Certification | J12: 45018 | K12: 46030 | L12: Resignation | M12: Inactive | N12: 11231.45 | O12: MGR-10454 | P12: 2.8 | Q12: =IF(Table1[[#This Row],[Tenure (Years)]]<1,"< 1 Year", IF(Table1[[#This Row],[Tenure (Years)]]<2,"1–2 Years", IF(Table1[[#This Row],[Tenure (Years)]]<3,"2–3 Years", IF(Table1[[#This Row],[Tenure (Years)]]<5,"3–5 Years", IF(Table1[[#This Row],[Tenure (Years)]]<10,"5–10 Years", "> 10 Years"))))) -> 2–3 Years | R12: =YEAR(Table1[[#This Row],[Hire Date]]) -> 2023 | S12: =YEAR(Table1[[#This Row],[Exit Date]]) -> 2026 | T12: =IF(Table1[[#This Row],[Education Level]]="Master's Degree", "Master's Degree", IF(Table1[[#This Row],[Education Level]]="Bachelor's Degree", "Bachelor's Degree", "Others")) -> Others
A13: EMP-10012 | B13: Kevin Rodriguez | C13: Male | D13: 30 | E13: Customer Service | F13: Central Hub | G13: Grade 3 – Mid-Level | H13: Permanent | I13: Bachelor's Degree | J13: 44303 | M13: Active | N13: 8805.8 | O13: MGR-10135 | P13: 5.1 | Q13: =IF(Table1[[#This Row],[Tenure (Years)]]<1,"< 1 Year", IF(Table1[[#This Row],[Tenure (Years)]]<2,"1–2 Years", IF(Table1[[#This Row],[Tenure (Years)]]<3,"2–3 Years", IF(Table1[[#This Row],[Tenure (Years)]]<5,"3–5 Years", IF(Table1[[#This Row],[Tenure (Years)]]<10,"5–10 Years", "> 10 Years"))))) -> 5–10 Years | R13: =YEAR(Table1[[#This Row],[Hire Date]]) -> 2021 | T13: =IF(Table1[[#This Row],[Education Level]]="Master's Degree", "Master's Degree", IF(Table1[[#This Row],[Education Level]]="Bachelor's Degree", "Bachelor's Degree", "Others")) -> Bachelor's Degree
A14: EMP-10013 | B14: Patrick Williams | C14: Male | D14: 37 | E14: Customer Service | F14: South Region | G14: Grade 3 – Mid-Level | H14: Permanent | I14: Bachelor's Degree | J14: 45662 | M14: Active | N14: 8023.05 | O14: MGR-10391 | P14: 1.4 | Q14: =IF(Table1[[#This Row],[Tenure (Years)]]<1,"< 1 Year", IF(Table1[[#This Row],[Tenure (Years)]]<2,"1–2 Years", IF(Table1[[#This Row],[Tenure (Years)]]<3,"2–3 Years", IF(Table1[[#This Row],[Tenure (Years)]]<5,"3–5 Years", IF(Table1[[#This Row],[Tenure (Years)]]<10,"5–10 Years", "> 10 Years"))))) -> 1–2 Years | R14: =YEAR(Table1[[#This Row],[Hire Date]]) -> 2025 | T14: =IF(Table1[[#This Row],[Education Level]]="Master's Degree", "Master's Degree", IF(Table1[[#This Row],[Education Level]]="Bachelor's Degree", "Bachelor's Degree", "Others")) -> Bachelor's Degree
A15: EMP-10014 | B15: Michael Griffith | C15: Male | D15: 22 | E15: Operations | F15: Head Office | G15: Grade 3 – Mid-Level | H15: Permanent | I15: Bachelor's Degree | J15: 43103 | M15: Active | N15: 8835.88 | O15: MGR-10426 | P15: 8.4 | Q15: =IF(Table1[[#This Row],[Tenure (Years)]]<1,"< 1 Year", IF(Table1[[#This Row],[Tenure (Years)]]<2,"1–2 Years", IF(Table1[[#This Row],[Tenure (Years)]]<3,"2–3 Years", IF(Table1[[#This Row],[Tenure (Years)]]<5,"3–5 Years", IF(Table1[[#This Row],[Tenure (Years)]]<10,"5–10 Years", "> 10 Years"))))) -> 5–10 Years | R15: =YEAR(Table1[[#This Row],[Hire Date]]) -> 2018 | T15: =IF(Table1[[#This Row],[Education Level]]="Master's Degree", "Master's Degree", IF(Table1[[#This Row],[Education Level]]="Bachelor's Degree", "Bachelor's Degree", "Others")) -> Bachelor's Degree
A16: EMP-10015 | B16: Carol Thornton | C16: Female | D16: 22 | E16: IT | F16: Head Office | G16: Grade 3 – Mid-Level | H16: Permanent | I16: Bachelor's Degree | J16: 43423 | M16: Active | N16: 7222.61 | O16: MGR-10393 | P16: 7.5 | Q16: =IF(Table1[[#This Row],[Tenure (Years)]]<1,"< 1 Year", IF(Table1[[#This Row],[Tenure (Years)]]<2,"1–2 Years", IF(Table1[[#This Row],[Tenure (Years)]]<3,"2–3 Years", IF(Table1[[#This Row],[Tenure (Years)]]<5,"3–5 Years", IF(Table1[[#This Row],[Tenure (Years)]]<10,"5–10 Years", "> 10 Years"))))) -> 5–10 Years | R16: =YEAR(Table1[[#This Row],[Hire Date]]) -> 2018 | T16: =IF(Table1[[#This Row],[Education Level]]="Master's Degree", "Master's Degree", IF(Table1[[#This Row],[Education Level]]="Bachelor's Degree", "Bachelor's Degree", "Others")) -> Bachelor's Degree
A17: EMP-10016 | B17: Nicholas Alexander | C17: Male | D17: 29 | E17: Operations | F17: Central Hub | G17: Grade 1 – Entry | H17: Permanent | I17: Bachelor's Degree | J17: 44186 | M17: Active | N17: 3212.92 | O17: MGR-10387 | P17: 5.4 | Q17: =IF(Table1[[#This Row],[Tenure (Years)]]<1,"< 1 Year", IF(Table1[[#This Row],[Tenure (Years)]]<2,"1–2 Years", IF(Table1[[#This Row],[Tenure (Years)]]<3,"2–3 Years", IF(Table1[[#This Row],[Tenure (Years)]]<5,"3–5 Years", IF(Table1[[#This Row],[Tenure (Years)]]<10,"5–10 Years", "> 10 Years"))))) -> 5–10 Years | R17: =YEAR(Table1[[#This Row],[Hire Date]]) -> 2020 | T17: =IF(Table1[[#This Row],[Education Level]]="Master's Degree", "Master's Degree", IF(Table1[[#This Row],[Education Level]]="Bachelor's Degree", "Bachelor's Degree", "Others")) -> Bachelor's Degree
A18: EMP-10017 | B18: Caitlin Morgan | C18: Female | D18: 25 | E18: Sales | F18: Head Office | G18: Grade 4 – Senior | H18: Permanent | I18: Bachelor's Degree | J18: 44630 | M18: Active | N18: 11295.47 | O18: MGR-10174 | P18: 4.2 | Q18: =IF(Table1[[#This Row],[Tenure (Years)]]<1,"< 1 Year", IF(Table1[[#This Row],[Tenure (Years)]]<2,"1–2 Years", IF(Table1[[#This Row],[Tenure (Years)]]<3,"2–3 Years", IF(Table1[[#This Row],[Tenure (Years)]]<5,"3–5 Years", IF(Table1[[#This Row],[Tenure (Years)]]<10,"5–10 Years", "> 10 Years"))))) -> 3–5 Years | R18: =YEAR(Table1[[#This Row],[Hire Date]]) -> 2022 | T18: =IF(Table1[[#This Row],[Education Level]]="Master's Degree", "Master's Degree", IF(Table1[[#This Row],[Education Level]]="Bachelor's Degree", "Bachelor's Degree", "Others")) -> Bachelor's Degree
A19: EMP-10018 | B19: Jeffrey Sanchez | C19: Male | D19: 37 | E19: Finance | F19: Head Office | G19: Grade 4 – Senior | H19: Permanent | I19: Diploma | J19: 43391 | K19: 45630 | L19: Resignation | M19: Inactive | N19: 10535.52 | O19: MGR-10122 | P19: 6.1 | Q19: =IF(Table1[[#This Row],[Tenure (Years)]]<1,"< 1 Year", IF(Table1[[#This Row],[Tenure (Years)]]<2,"1–2 Years", IF(Table1[[#This Row],[Tenure (Years)]]<3,"2–3 Years", IF(Table1[[#This Row],[Tenure (Years)]]<5,"3–5 Years", IF(Table1[[#This Row],[Tenure (Years)]]<10,"5–10 Years", "> 10 Years"))))) -> 5–10 Years | R19: =YEAR(Table1[[#This Row],[Hire Date]]) -> 2018 | S19: =YEAR(Table1[[#This Row],[Exit Date]]) -> 2024 | T19: =IF(Table1[[#This Row],[Education Level]]="Master's Degree", "Master's Degree", IF(Table1[[#This Row],[Education Level]]="Bachelor's Degree", "Bachelor's Degree", "Others")) -> Others
A20: EMP-10019 | B20: Andrew Mcconnell | C20: Male | D20: 26 | E20: IT | F20: North Region | G20: Grade 4 – Senior | H20: Permanent | I20: Bachelor's Degree | J20: 45439 | M20: Active | N20: 10464.07 | O20: MGR-10049 | P20: 2 | Q20: =IF(Table1[[#This Row],[Tenure (Years)]]<1,"< 1 Year", IF(Table1[[#This Row],[Tenure (Years)]]<2,"1–2 Years", IF(Table1[[#This Row],[Tenure (Years)]]<3,"2–3 Years", IF(Table1[[#This Row],[Tenure (Years)]]<5,"3–5 Years", IF(Table1[[#This Row],[Tenure (Years)]]<10,"5–10 Years", "> 10 Years"))))) -> 2–3 Years | R20: =YEAR(Table1[[#This Row],[Hire Date]]) -> 2024 | T20: =IF(Table1[[#This Row],[Education Level]]="Master's Degree", "Master's Degree", IF(Table1[[#This Row],[Education Level]]="Bachelor's Degree", "Bachelor's Degree", "Others")) -> Bachelor's Degree
A21: EMP-10020 | B21: Terry Armstrong | C21: Male | D21: 22 | E21: Human Resources | F21: South Region | G21: Grade 4 – Senior | H21: Permanent | I21: Master's Degree | J21: 46087 | M21: Active | N21: 11094.34 | O21: MGR-10032 | P21: 0.2 | Q21: =IF(Table1[[#This Row],[Tenure (Years)]]<1,"< 1 Year", IF(Table1[[#This Row],[Tenure (Years)]]<2,"1–2 Years", IF(Table1[[#This Row],[Tenure (Years)]]<3,"2–3 Years", IF(Table1[[#This Row],[Tenure (Years)]]<5,"3–5 Years", IF(Table1[[#This Row],[Tenure (Years)]]<10,"5–10 Years", "> 10 Years"))))) -> < 1 Year | R21: =YEAR(Table1[[#This Row],[Hire Date]]) -> 2026 | T21: =IF(Table1[[#This Row],[Education Level]]="Master's Degree", "Master's Degree", IF(Table1[[#This Row],[Education Level]]="Bachelor's Degree", "Bachelor's Degree", "Others")) -> Master's Degree
A22: EMP-10021 | B22: Eric Anderson | C22: Male | D22: 48 | E22: Marketing | F22: North Region | G22: Grade 4 – Senior | H22: Permanent | I22: Bachelor's Degree | J22: 43885 | M22: Active | N22: 13102.67 | O22: MGR-10128 | P22: 6.2 | Q22: =IF(Table1[[#This Row],[Tenure (Years)]]<1,"< 1 Year", IF(Table1[[#This Row],[Tenure (Years)]]<2,"1–2 Years", IF(Table1[[#This Row],[Tenure (Years)]]<3,"2–3 Years", IF(Table1[[#This Row],[Tenure (Years)]]<5,"3–5 Years", IF(Table1[[#This Row],[Tenure (Years)]]<10,"5–10 Years", "> 10 Years"))))) -> 5–10 Years | R22: =YEAR(Table1[[#This Row],[Hire Date]]) -> 2020 | T22: =IF(Table1[[#This Row],[Education Level]]="Master's Degree", "Master's Degree", IF(Table1[[#This Row],[Education Level]]="Bachelor's Degree", "Bachelor's Degree", "Others")) -> Bachelor's Degree
A23: EMP-10022 | B23: Jenna Butler | C23: Female | D23: 32 | E23: Human Resources | F23: Head Office | G23: Grade 3 – Mid-Level | H23: Permanent | I23: Bachelor's Degree | J23: 43308 | K23: 46063 | L23: Redundancy | M23: Inactive | N23: 9084.05 | O23: MGR-10086 | P23: 7.5 | Q23: =IF(Table1[[#This Row],[Tenure (Years)]]<1,"< 1 Year", IF(Table1[[#This Row],[Tenure (Years)]]<2,"1–2 Years", IF(Table1[[#This Row],[Tenure (Years)]]<3,"2–3 Years", IF(Table1[[#This Row],[Tenure (Years)]]<5,"3–5 Years", IF(Table1[[#This Row],[Tenure (Years)]]<10,"5–10 Years", "> 10 Years"))))) -> 5–10 Years | R23: =YEAR(Table1[[#This Row],[Hire Date]]) -> 2018 | S23: =YEAR(Table1[[#This Row],[Exit Date]]) -> 2026 | T23: =IF(Table1[[#This Row],[Education Level]]="Master's Degree", "Master's Degree", IF(Table1[[#This Row],[Education Level]]="Bachelor's Degree", "Bachelor's Degree", "Others")) -> Bachelor's Degree
A24: EMP-10023 | B24: Adam Ross | C24: Male | D24: 35 | E24: Marketing | F24: North Region | G24: Grade 3 – Mid-Level | H24: Permanent | I24: High School | J24: 43341 | M24: Active | N24: 7141.24 | O24: MGR-10402 | P24: 7.7 | Q24: =IF(Table1[[#This Row],[Tenure (Years)]]<1,"< 1 Year", IF(Table1[[#This Row],[Tenure (Years)]]<2,"1–2 Years", IF(Table1[[#This Row],[Tenure (Years)]]<3,"2–3 Years", IF(Table1[[#This Row],[Tenure (Years)]]<5,"3–5 Years", IF(Table1[[#This Row],[Tenure (Years)]]<10,"5–10 Years", "> 10 Years"))))) -> 5–10 Years | R24: =YEAR(Table1[[#This Row],[Hire Date]]) -> 2018 | T24: =IF(Table1[[#This Row],[Education Level]]="Master's Degree", "Master's Degree", IF(Table1[[#This Row],[Education Level]]="Bachelor's Degree", "Bachelor's Degree", "Others")) -> Others
A25: EMP-10024 | B25: Andrea Hall | C25: Female | D25: 22 | E25: Risk & Compliance | F25: Head Office | G25: Grade 3 – Mid-Level | H25: Permanent | I25: Bachelor's Degree | J25: 45377 | M25: Active | N25: 8589.77 | O25: MGR-10030 | P25: 2.1 | Q25: =IF(Table1[[#This Row],[Tenure (Years)]]<1,"< 1 Year", IF(Table1[[#This Row],[Tenure (Years)]]<2,"1–2 Years", IF(Table1[[#This Row],[Tenure (Years)]]<3,"2–3 Years", IF(Table1[[#This Row],[Tenure (Years)]]<5,"3–5 Years", IF(Table1[[#This Row],[Tenure (Years)]]<10,"5–10 Years", "> 10 Years"))))) -> 2–3 Years | R25: =YEAR(Table1[[#This Row],[Hire Date]]) -> 2024 | T25: =IF(Table1[[#This Row],[Education Level]]="Master's Degree", "Master's Degree", IF(Table1[[#This Row],[Education Level]]="Bachelor's Degree", "Bachelor's Degree", "Others")) -> Bachelor's Degree
A26: EMP-10025 | B26: David Savage | C26: Male | D26: 30 | E26: Procurement | F26: West Region | G26: Grade 4 – Senior | H26: Permanent | I26: Bachelor's Degree | J26: 43306 | M26: Active | N26: 9774.31 | O26: MGR-10492 | P26: 7.8 | Q26: =IF(Table1[[#This Row],[Tenure (Years)]]<1,"< 1 Year", IF(Table1[[#This Row],[Tenure (Years)]]<2,"1–2 Years", IF(Table1[[#This Row],[Tenure (Years)]]<3,"2–3 Years", IF(Table1[[#This Row],[Tenure (Years)]]<5,"3–5 Years", IF(Table1[[#This Row],[Tenure (Years)]]<10,"5–10 Years", "> 10 Years"))))) -> 5–10 Years | R26: =YEAR(Table1[[#This Row],[Hire Date]]) -> 2018 | T26: =IF(Table1[[#This Row],[Education Level]]="Master's Degree", "Master's Degree", IF(Table1[[#This Row],[Education Level]]="Bachelor's Degree", "Bachelor's Degree", "Others")) -> Bachelor's Degree
A27: EMP-10026 | B27: Elizabeth Matthews | C27: Female | D27: 35 | E27: Customer Service | F27: Central Hub | G27: Grade 1 – Entry | H27: Contract | I27: Bachelor's Degree | J27: 45866 | M27: Active | N27: 2778.74 | O27: MGR-10021 | P27: 0.8 | Q27: =IF(Table1[[#This Row],[Tenure (Years)]]<1,"< 1 Year", IF(Table1[[#This Row],[Tenure (Years)]]<2,"1–2 Years", IF(Table1[[#This Row],[Tenure (Years)]]<3,"2–3 Years", IF(Table1[[#This Row],[Tenure (Years)]]<5,"3–5 Years", IF(Table1[[#This Row],[Tenure (Years)]]<10,"5–10 Years", "> 10 Years"))))) -> < 1 Year | R27: =YEAR(Table1[[#This Row],[Hire Date]]) -> 2025 | T27: =IF(Table1[[#This Row],[Education Level]]="Master's Degree", "Master's Degree", IF(Table1[[#This Row],[Education Level]]="Bachelor's Degree", "Bachelor's Degree", "Others")) -> Bachelor's Degree
A28: EMP-10027 | B28: Paula Cunningham | C28: Female | D28: 24 | E28: Procurement | F28: East Region | G28: Grade 1 – Entry | H28: Internship | I28: Bachelor's Degree | J28: 44396 | K28: 44639 | L28: End of Contract | M28: Inactive | N28: 3486.06 | O28: MGR-10235 | P28: 0.7 | Q28: =IF(Table1[[#This Row],[Tenure (Years)]]<1,"< 1 Year", IF(Table1[[#This Row],[Tenure (Years)]]<2,"1–2 Years", IF(Table1[[#This Row],[Tenure (Years)]]<3,"2–3 Years", IF(Table1[[#This Row],[Tenure (Years)]]<5,"3–5 Years", IF(Table1[[#This Row],[Tenure (Years)]]<10,"5–10 Years", "> 10 Years"))))) -> < 1 Year | R28: =YEAR(Table1[[#This Row],[Hire Date]]) -> 2021 | S28: =YEAR(Table1[[#This Row],[Exit Date]]) -> 2022 | T28: =IF(Table1[[#This Row],[Education Level]]="Master's Degree", "Master's Degree", IF(Table1[[#This Row],[Education Level]]="Bachelor's Degree", "Bachelor's Degree", "Others")) -> Bachelor's Degree
A29: EMP-10028 | B29: Robert Campbell | C29: Male | D29: 38 | E29: Legal | F29: Head Office | G29: Grade 6 – Manager | H29: Part-Time | I29: Professional Certification | J29: 45645 | M29: Active | N29: 29357.34 | O29: MGR-10136 | P29: 1.4 | Q29: =IF(Table1[[#This Row],[Tenure (Years)]]<1,"< 1 Year", IF(Table1[[#This Row],[Tenure (Years)]]<2,"1–2 Years", IF(Table1[[#This Row],[Tenure (Years)]]<3,"2–3 Years", IF(Table1[[#This Row],[Tenure (Years)]]<5,"3–5 Years", IF(Table1[[#This Row],[Tenure (Years)]]<10,"5–10 Years", "> 10 Years"))))) -> 1–2 Years | R29: =YEAR(Table1[[#This Row],[Hire Date]]) -> 2024 | T29: =IF(Table1[[#This Row],[Education Level]]="Master's Degree", "Master's Degree", IF(Table1[[#This Row],[Education Level]]="Bachelor's Degree", "Bachelor's Degree", "Others")) -> Others
A30: EMP-10029 | B30: Elizabeth Armstrong | C30: Female | D30: 29 | E30: Operations | F30: South Region | G30: Grade 5 – Lead | H30: Permanent | I30: Bachelor's Degree | J30: 44614 | M30: Active | N30: 19285.19 | O30: MGR-10414 | P30: 4.2 | Q30: =IF(Table1[[#This Row],[Tenure (Years)]]<1,"< 1 Year", IF(Table1[[#This Row],[Tenure (Years)]]<2,"1–2 Years", IF(Table1[[#This Row],[Tenure (Years)]]<3,"2–3 Years", IF(Table1[[#This Row],[Tenure (Years)]]<5,"3–5 Years", IF(Table1[[#This Row],[Tenure (Years)]]<10,"5–10 Years", "> 10 Years"))))) -> 3–5 Years | R30: =YEAR(Table1[[#This Row],[Hire Date]]) -> 2022 | T30: =IF(Table1[[#This Row],[Education Level]]="Master's Degree", "Master's Degree", IF(Table1[[#This Row],[Education Level]]="Bachelor's Degree", "Bachelor's Degree", "Others")) -> Bachelor's Degree
A31: EMP-10030 | B31: Julie Thompson | C31: Female | D31: 32 | E31: Executive Management | F31: Head Office | G31: Grade 7 – Director | H31: Permanent | I31: Master's Degree | J31: 45818 | M31: Active | N31: 40017.95 | O31: N/A | P31: 0.9 | Q31: =IF(Table1[[#This Row],[Tenure (Years)]]<1,"< 1 Year", IF(Table1[[#This Row],[Tenure (Years)]]<2,"1–2 Years", IF(Table1[[#This Row],[Tenure (Years)]]<3,"2–3 Years", IF(Table1[[#This Row],[Tenure (Years)]]<5,"3–5 Years", IF(Table1[[#This Row],[Tenure (Years)]]<10,"5–10 Years", "> 10 Years"))))) -> < 1 Year | R31: =YEAR(Table1[[#This Row],[Hire Date]]) -> 2025 | T31: =IF(Table1[[#This Row],[Education Level]]="Master's Degree", "Master's Degree", IF(Table1[[#This Row],[Education Level]]="Bachelor's Degree", "Bachelor's Degree", "Others")) -> Master's Degree
A32: EMP-10031 | B32: Stephen Hodges | C32: Male | D32: 29 | E32: Customer Service | F32: Head Office | G32: Grade 1 – Entry | H32: Permanent | I32: Bachelor's Degree | J32: 44505 | M32: Active | N32: 2922.63 | O32: MGR-10464 | P32: 4.5 | Q32: =IF(Table1[[#This Row],[Tenure (Years)]]<1,"< 1 Year", IF(Table1[[#This Row],[Tenure (Years)]]<2,"1–2 Years", IF(Table1[[#This Row],[Tenure (Years)]]<3,"2–3 Years", IF(Table1[[#This Row],[Tenure (Years)]]<5,"3–5 Years", IF(Table1[[#This Row],[Tenure (Years)]]<10,"5–10 Years", "> 10 Years"))))) -> 3–5 Years | R32: =YEAR(Table1[[#This Row],[Hire Date]]) -> 2021 | T32: =IF(Table1[[#This Row],[Education Level]]="Master's Degree", "Master's Degree", IF(Table1[[#This Row],[Education Level]]="Bachelor's Degree", "Bachelor's Degree", "Others")) -> Bachelor's Degree
A33: EMP-10032 | B33: Guy Blevins | C33: Male | D33: 51 | E33: Finance | F33: Central Hub | G33: Grade 2 – Junior | H33: Permanent | I33: Diploma | J33: 43115 | M33: Active | N33: 5058.94 | O33: MGR-10227 | P33: 8.3 | Q33: =IF(Table1[[#This Row],[Tenure (Years)]]<1,"< 1 Year", IF(Table1[[#This Row],[Tenure (Years)]]<2,"1–2 Years", IF(Table1[[#This Row],[Tenure (Years)]]<3,"2–3 Years", IF(Table1[[#This Row],[Tenure (Years)]]<5,"3–5 Years", IF(Table1[[#This Row],[Tenure (Years)]]<10,"5–10 Years", "> 10 Years"))))) -> 5–10 Years | R33: =YEAR(Table1[[#This Row],[Hire Date]]) -> 2018 | T33: =IF(Table1[[#This Row],[Education Level]]="Master's Degree", "Master's Degree", IF(Table1[[#This Row],[Education Level]]="Bachelor's Degree", "Bachelor's Degree", "Others")) -> Others
A34: EMP-10033 | B34: Kevin Miranda | C34: Male | D34: 34 | E34: Customer Service | F34: West Region | G34: Grade 3 – Mid-Level | H34: Internship | I34: Bachelor's Degree | J34: 45931 | K34: 46086 | L34: End of Contract | M34: Inactive | N34: 8182.72 | O34: MGR-10022 | P34: 0.4 | Q34: =IF(Table1[[#This Row],[Tenure (Years)]]<1,"< 1 Year", IF(Table1[[#This Row],[Tenure (Years)]]<2,"1–2 Years", IF(Table1[[#This Row],[Tenure (Years)]]<3,"2–3 Years", IF(Table1[[#This Row],[Tenure (Years)]]<5,"3–5 Years", IF(Table1[[#This Row],[Tenure (Years)]]<10,"5–10 Years", "> 10 Years"))))) -> < 1 Year | R34: =YEAR(Table1[[#This Row],[Hire Date]]) -> 2025 | S34: =YEAR(Table1[[#This Row],[Exit Date]]) -> 2026 | T34: =IF(Table1[[#This Row],[Education Level]]="Master's Degree", "Master's Degree", IF(Table1[[#This Row],[Education Level]]="Bachelor's Degree", "Bachelor's Degree", "Others")) -> Bachelor's Degree
A35: EMP-10034 | B35: Virginia Smith | C35: Female | D35: 25 | E35: IT | F35: Head Office | G35: Grade 3 – Mid-Level | H35: Contract | I35: Bachelor's Degree | J35: 43264 | K35: 46090 | L35: End of Contract | M35: Inactive | N35: 9299.26 | O35: MGR-10448 | P35: 7.7 | Q35: =IF(Table1[[#This Row],[Tenure (Years)]]<1,"< 1 Year", IF(Table1[[#This Row],[Tenure (Years)]]<2,"1–2 Years", IF(Table1[[#This Row],[Tenure (Years)]]<3,"2–3 Years", IF(Table1[[#This Row],[Tenure (Years)]]<5,"3–5 Years", IF(Table1[[#This Row],[Tenure (Years)]]<10,"5–10 Years", "> 10 Years"))))) -> 5–10 Years | R35: =YEAR(Table1[[#This Row],[Hire Date]]) -> 2018 | S35: =YEAR(Table1[[#This Row],[Exit Date]]) -> 2026 | T35: =IF(Table1[[#This Row],[Education Level]]="Master's Degree", "Master's Degree", IF(Table1[[#This Row],[Education Level]]="Bachelor's Degree", "Bachelor's Degree", "Others")) -> Bachelor's Degree
A36: EMP-10035 | B36: Katrina Nguyen | C36: Female | D36: 42 | E36: Marketing | F36: West Region | G36: Grade 7 – Director | H36: Contract | I36: Professional Certification | J36: 44070 | K36: 44590 | L36: End of Contract | M36: Inactive | N36: 41242.16 | O36: N/A | P36: 1.4 | Q36: =IF(Table1[[#This Row],[Tenure (Years)]]<1,"< 1 Year", IF(Table1[[#This Row],[Tenure (Years)]]<2,"1–2 Years", IF(Table1[[#This Row],[Tenure (Years)]]<3,"2–3 Years", IF(Table1[[#This Row],[Tenure (Years)]]<5,"3–5 Years", IF(Table1[[#This Row],[Tenure (Years)]]<10,"5–10 Years", "> 10 Years"))))) -> 1–2 Years | R36: =YEAR(Table1[[#This Row],[Hire Date]]) -> 2020 | S36: =YEAR(Table1[[#This Row],[Exit Date]]) -> 2022 | T36: =IF(Table1[[#This Row],[Education Level]]="Master's Degree", "Master's Degree", IF(Table1[[#This Row],[Education Level]]="Bachelor's Degree", "Bachelor's Degree", "Others")) -> Others
A37: EMP-10036 | B37: Mary Clarke | C37: Female | D37: 24 | E37: Marketing | F37: North Region | G37: Grade 5 – Lead | H37: Permanent | I37: Master's Degree | J37: 44193 | K37: 45773 | L37: Resignation | M37: Inactive | N37: 19184.38 | O37: MGR-10419 | P37: 4.3 | Q37: =IF(Table1[[#This Row],[Tenure (Years)]]<1,"< 1 Year", IF(Table1[[#This Row],[Tenure (Years)]]<2,"1–2 Years", IF(Table1[[#This Row],[Tenure (Years)]]<3,"2–3 Years", IF(Table1[[#This Row],[Tenure (Years)]]<5,"3–5 Years", IF(Table1[[#This Row],[Tenure (Years)]]<10,"5–10 Years", "> 10 Years"))))) -> 3–5 Years | R37: =YEAR(Table1[[#This Row],[Hire Date]]) -> 2020 | S37: =YEAR(Table1[[#This Row],[Exit Date]]) -> 2025 | T37: =IF(Table1[[#This Row],[Education Level]]="Master's Degree", "Master's Degree", IF(Table1[[#This Row],[Education Level]]="Bachelor's Degree", "Bachelor's Degree", "Others")) -> Master's Degree
A38: EMP-10037 | B38: Ashley Clark | C38: Female | D38: 36 | E38: Risk & Compliance | F38: Head Office | G38: Grade 3 – Mid-Level | H38: Permanent | I38: Bachelor's Degree | J38: 44014 | M38: Active | N38: 8961.61 | O38: MGR-10496 | P38: 5.9 | Q38: =IF(Table1[[#This Row],[Tenure (Years)]]<1,"< 1 Year", IF(Table1[[#This Row],[Tenure (Years)]]<2,"1–2 Years", IF(Table1[[#This Row],[Tenure (Years)]]<3,"2–3 Years", IF(Table1[[#This Row],[Tenure (Years)]]<5,"3–5 Years", IF(Table1[[#This Row],[Tenure (Years)]]<10,"5–10 Years", "> 10 Years"))))) -> 5–10 Years | R38: =YEAR(Table1[[#This Row],[Hire Date]]) -> 2020 | T38: =IF(Table1[[#This Row],[Education Level]]="Master's Degree", "Master's Degree", IF(Table1[[#This Row],[Education Level]]="Bachelor's Degree", "Bachelor's Degree", "Others")) -> Bachelor's Degree
A39: EMP-10038 | B39: Cynthia White | C39: Female | D39: 22 | E39: IT | F39: West Region | G39: Grade 3 – Mid-Level | H39: Permanent | I39: High School | J39: 45297 | M39: Active | N39: 8028.22 | O39: MGR-10298 | P39: 2.4 | Q39: =IF(Table1[[#This Row],[Tenure (Years)]]<1,"< 1 Year", IF(Table1[[#This Row],[Tenure (Years)]]<2,"1–2 Years", IF(Table1[[#This Row],[Tenure (Years)]]<3,"2–3 Years", IF(Table1[[#This Row],[Tenure (Years)]]<5,"3–5 Years", IF(Table1[[#This Row],[Tenure (Years)]]<10,"5–10 Years", "> 10 Years"))))) -> 2–3 Years | R39: =YEAR(Table1[[#This Row],[Hire Date]]) -> 2024 | T39: =IF(Table1[[#This Row],[Education Level]]="Master's Degree", "Master's Degree", IF(Table1[[#This Row],[Education Level]]="Bachelor's Degree", "Bachelor's Degree", "Others")) -> Others
A40: EMP-10039 | B40: Trevor Williams | C40: Male | D40: 23 | E40: IT | F40: Head Office | G40: Grade 1 – Entry | H40: Permanent | I40: Professional Certification | J40: 44385 | M40: Active | N40: 3394.86 | O40: MGR-10098 | P40: 4.9 | Q40: =IF(Table1[[#This Row],[Tenure (Years)]]<1,"< 1 Year", IF(Table1[[#This Row],[Tenure (Years)]]<2,"1–2 Years", IF(Table1[[#This Row],[Tenure (Years)]]<3,"2–3 Years", IF(Table1[[#This Row],[Tenure (Years)]]<5,"3–5 Years", IF(Table1[[#This Row],[Tenure (Years)]]<10,"5–10 Years", "> 10 Years"))))) -> 3–5 Years | R40: =YEAR(Table1[[#This Row],[Hire Date]]) -> 2021 | T40: =IF(Table1[[#This Row],[Education Level]]="Master's Degree", "Master's Degree", IF(Table1[[#This Row],[Education Level]]="Bachelor's Degree", "Bachelor's Degree", "Others")) -> Others
...

Sheet CALCULATION SHEET
A1: HEADCOUNT
B4: HEADCOUNT BY DEPT | E4: GENDER DIST | H4: EMPLOYMENT TYPE | K4: EDUCATION LEVEL DIST | N4: HEADCOUNT BY JOBGRADE
B5: Hire Year | C5: (All) | E5: Hire Year | F5: (All) | H5: Hire Year | I5: (All) | K5: Hire Year | L5: (All) | N5: Hire Year | O5: (All)
B6: Status | C6: Active | E6: Status | F6: Active | H6: Status | I6: Active | K6: Status | L6: Active | N6: Status | O6: (All)
B8: Row Labels | C8: Count of Employee ID | E8: Row Labels | F8: Count of Gender | H8: Row Labels | I8: Count of Employment Type | K8: Row Labels | L8: Count of Education Level Cleaned | N8: Row Labels | O8: Count of Employee ID | P8: Count of Employee ID2 | Q8: Average of Monthly Salary ($) | R8: Min. of Monthly Salary ($) | S8: Min. of Monthly Salary ($)2
B9: Risk & Compliance | C9: 379 | E9: Male | F9: 0.5543131 | H9: Internship | I9: 0.024418074 | K9: Bachelor's Degree | L9: 0.50319489 | N9: Grade 1 – Entry | O9: 431 | P9: 0.078363636 | Q9: 3200.497 | R9: 2504.71 | S9: 2504.71
B10: Finance | C10: 383 | E10: Female | F10: 0.4456869 | H10: Part-Time | I10: 0.039707896 | K10: Master's Degree | L10: 0.27453218 | N10: Grade 2 – Junior | O10: 977 | P10: 0.17763636 | Q10: 5297.4411 | R10: 4000.09 | S10: 4000.09
B11: IT | C11: 385 | E11: Grand Total | F11: 1 | H11: Contract | I11: 0.14103149 | K11: Others | L11: 0.22227293 | N11: Grade 3 – Mid-Level | O11: 1336 | P11: 0.24290909 | Q11: 8023.6775 | R11: 6500.74 | S11: 6500.74
B12: Human Resources | C12: 393 | H12: Permanent | I12: 0.79484254 | K12: Grand Total | L12: 1 | N12: Grade 4 – Senior | O12: 1162 | P12: 0.21127273 | Q12: 11740.221 | R12: 9504.89 | S12: 9504.89
B13: Operations | C13: 393 | H13: Grand Total | I13: 1 | N13: Grade 5 – Lead | O13: 622 | P13: 0.11309091 | Q13: 16967.766 | R13: 14004.05 | S13: 14004.05
B14: Legal | C14: 398 | N14: Grade 6 – Manager | O14: 478 | P14: 0.086909091 | Q14: 24897.852 | R14: 20000.78 | S14: 20000.78
B15: Customer Service | C15: 400 | N15: Grade 7 – Director | O15: 314 | P15: 0.057090909 | Q15: 37643.612 | R15: 30019.68 | S15: 30019.68
B16: Sales | C16: 402 | N16: Grade 8 – Executive | O16: 180 | P16: 0.032727273 | Q16: 57750.605 | R16: 45156.31 | S16: 45156.31
B17: Procurement | C17: 407 | N17: Grand Total | O17: 5500 | P17: 1 | Q17: 13743.111 | R17: 2504.71 | S17: 2504.71
B18: Executive Management | C18: 420
B19: Marketing | C19: 422
B20: Grand Total | C20: 4382
B25: HEADCOUNT BY JOB GRADE | E25: HEADCOUNT BY BRANCH | I25: GENDER DIST BY BRANCH | M25: NEW HIRES YTD | P25: ACTIVE HEADCOUNT | S25: GENDER REPRESENTATION
B26: Hire Year | C26: (All) | E26: Hire Year | F26: (All) | I26: Hire Year | J26: (All) | M26: Hire Year | N26: 2026 | P26: Hire Year | Q26: (All) | S26: Hire Year | T26: (All)
B27: Status | C27: Active | E27: Status | F27: Active | I27: Status | J27: Active | P27: Status | Q27: Active | S27: Status | T27: Active
M28: Count of Employee ID
B29: Row Labels | C29: Count of Employee ID | E29: Row Labels | F29: Count of Employee ID | G29: Count of Employee ID2 | I29: Count of Employee ID | J29: Column Labels | M29: 160 | P29: Count of Employee ID | S29: Row Labels | T29: Count of Employee ID
B30: Grade 3 – Mid-Level | C30: 1064 | E30: Central Hub | F30: 486 | G30: 0.11090826 | I30: Row Labels | J30: Male | K30: Female | P30: 4382 | S30: Female | T30: 0.4456869
B31: Grade 4 – Senior | C31: 916 | E31: East Region | F31: 525 | G31: 0.11980831 | I31: Central Hub | J31: 268 | K31: 218 | S31: Male | T31: 0.5543131
B32: Grade 2 – Junior | C32: 796 | E32: Head Office | F32: 1543 | G32: 0.35212232 | I32: East Region | J32: 292 | K32: 233 | S32: Grand Total | T32: 1
B33: Grade 5 – Lead | C33: 499 | E33: North Region | F33: 648 | G33: 0.14787768 | I33: Head Office | J33: 853 | K33: 690
B34: Grade 6 – Manager | C34: 381 | E34: South Region | F34: 661 | G34: 0.15084436 | I34: North Region | J34: 368 | K34: 280
B35: Grade 1 – Entry | C35: 344 | E35: West Region | F35: 519 | G35: 0.11843907 | I35: South Region | J35: 356 | K35: 305
B36: Grade 7 – Director | C36: 249 | E36: Grand Total | F36: 4382 | G36: 1 | I36: West Region | J36: 292 | K36: 227
B37: Grade 8 – Executive | C37: 133 | I37: Grand Total | J37: 2429 | K37: 1953
B38: Grand Total | C38: 4382
B43: HEADCOUNT BY DEPT | F43: HEADCOUNT BY DEPT BY GENDER | K43: HEADCOUNT BY DEPT BY EMP TYPE | P43: HEADCOUNT BY DEPT BY AVG SALARY
B44: Hire Year | C44: (All) | F44: Hire Year | G44: (All) | K44: Hire Year | L44: (All) | P44: Hire Year | Q44: (All)
B45: Status | C45: Active | F45: Status | G45: Active | K45: Status | L45: Active | P45: Status | Q45: Active
B47: Row Labels | C47: Count of Employee ID | D47: Count of Employee ID2 | F47: Count of Employee ID | G47: Column Labels | K47: Count of Employee ID | L47: Column Labels | P47: Row Labels | Q47: Average of Monthly Salary ($)
B48: Risk & Compliance | C48: 379 | D48: 0.086490187 | F48: Row Labels | G48: Male | H48: Female | I48: Grand Total | K48: Row Labels | L48: Permanent | M48: Contract | N48: Grand Total | P48: Human Resources | Q48: 11397.239
B49: Finance | C49: 383 | D49: 0.087403012 | F49: Human Resources | G49: 238 | H49: 155 | I49: 393 | K49: Human Resources | L49: 316 | M49: 53 | N49: 369 | P49: Customer Service | Q49: 7641.1852
B50: IT | C50: 385 | D50: 0.087859425 | F50: Customer Service | G50: 237 | H50: 163 | I50: 400 | K50: Customer Service | L50: 318 | M50: 55 | N50: 373 | P50: Procurement | Q50: 9839.0264
B51: Human Resources | C51: 393 | D51: 0.089685075 | F51: Procurement | G51: 215 | H51: 192 | I51: 407 | K51: Procurement | L51: 319 | M51: 58 | N51: 377 | P51: Risk & Compliance | Q51: 13334.206
B52: Operations | C52: 393 | D52: 0.089685075 | F52: Risk & Compliance | G52: 208 | H52: 171 | I52: 379 | K52: Risk & Compliance | L52: 302 | M52: 53 | N52: 355 | P52: Sales | Q52: 10962.322
...

Sheet DASHBOARD OVERVIEW
A6: DASHBOARD
B8: Overview
B10: Headcount
B12: Attrition
B14: Training & ROI
A20: Period: Jan 2024 – May 2026

Sheet HEADCOUNT ANALYSIS
D1: HEADCOUNT ANALYSIS
A6: DASHBOARD
B8: Overview
B10: Headcount
B12: Attrition
B14: Training & ROI
E19: DEPARTMENT | H19: HEADCOUNT | J19: % OF TOTAL | L19: MALE | M19: FEMALE | N19: PERMANENT | P19: CONTRACT | R19: AVG. SALARY | T19: DISTRIBUTION
A20: Period: Jan 2024 – May 2026
E21: Human Resources | H21: ='CALCULATION SHEET'!C48 -> 379 | J21: ='CALCULATION SHEET'!D48 -> 0.086490187 | L21: ='CALCULATION SHEET'!G49 -> 238 | M21: ='CALCULATION SHEET'!H49 -> 155 | N21: ='CALCULATION SHEET'!L49 -> 316 | P21: ='CALCULATION SHEET'!M49 -> 53 | R21: ='CALCULATION SHEET'!Q48 -> 11397.239 | T21: =H21 -> 379
E22: Customer Service | H22: ='CALCULATION SHEET'!C49 -> 383 | J22: ='CALCULATION SHEET'!D49 -> 0.087403012 | L22: ='CALCULATION SHEET'!G50 -> 237 | M22: ='CALCULATION SHEET'!H50 -> 163 | N22: ='CALCULATION SHEET'!L50 -> 318 | P22: ='CALCULATION SHEET'!M50 -> 55 | R22: ='CALCULATION SHEET'!Q49 -> 7641.1852 | T22: =H22 -> 383
E23: Procurement | H23: ='CALCULATION SHEET'!C50 -> 385 | J23: ='CALCULATION SHEET'!D50 -> 0.087859425 | L23: ='CALCULATION SHEET'!G51 -> 215 | M23: ='CALCULATION SHEET'!H51 -> 192 | N23: ='CALCULATION SHEET'!L51 -> 319 | P23: ='CALCULATION SHEET'!M51 -> 58 | R23: ='CALCULATION SHEET'!Q50 -> 9839.0264 | T23: =H23 -> 385
E24: Risk & Compliance | H24: ='CALCULATION SHEET'!C51 -> 393 | J24: ='CALCULATION SHEET'!D51 -> 0.089685075 | L24: ='CALCULATION SHEET'!G52 -> 208 | M24: ='CALCULATION SHEET'!H52 -> 171 | N24: ='CALCULATION SHEET'!L52 -> 302 | P24: ='CALCULATION SHEET'!M52 -> 53 | R24: ='CALCULATION SHEET'!Q51 -> 13334.206 | T24: =H24 -> 393
E25: Sales | H25: ='CALCULATION SHEET'!C52 -> 393 | J25: ='CALCULATION SHEET'!D52 -> 0.089685075 | L25: ='CALCULATION SHEET'!G53 -> 203 | M25: ='CALCULATION SHEET'!H53 -> 199 | N25: ='CALCULATION SHEET'!L53 -> 327 | P25: ='CALCULATION SHEET'!M53 -> 53 | R25: ='CALCULATION SHEET'!Q52 -> 10962.322 | T25: =H25 -> 393
E26: Operations | H26: ='CALCULATION SHEET'!C53 -> 398 | J26: ='CALCULATION SHEET'!D53 -> 0.090826107 | L26: ='CALCULATION SHEET'!G54 -> 223 | M26: ='CALCULATION SHEET'!H54 -> 170 | N26: ='CALCULATION SHEET'!L54 -> 321 | P26: ='CALCULATION SHEET'!M54 -> 47 | R26: ='CALCULATION SHEET'!Q53 -> 8927.6525 | T26: =H26 -> 398
E27: Information Technology | H27: ='CALCULATION SHEET'!C54 -> 400 | J27: ='CALCULATION SHEET'!D54 -> 0.091282519 | L27: ='CALCULATION SHEET'!G55 -> 217 | M27: ='CALCULATION SHEET'!H55 -> 166 | N27: ='CALCULATION SHEET'!L55 -> 283 | P27: ='CALCULATION SHEET'!M55 -> 67 | R27: ='CALCULATION SHEET'!Q54 -> 12996.056 | T27: =H27 -> 400
E28: Finance | H28: ='CALCULATION SHEET'!C55 -> 402 | J28: ='CALCULATION SHEET'!D55 -> 0.091738932 | L28: ='CALCULATION SHEET'!G56 -> 220 | M28: ='CALCULATION SHEET'!H56 -> 202 | N28: ='CALCULATION SHEET'!L56 -> 346 | P28: ='CALCULATION SHEET'!M56 -> 55 | R28: ='CALCULATION SHEET'!Q55 -> 10248.675 | T28: =H28 -> 402
E29: Marketing | H29: ='CALCULATION SHEET'!C56 -> 407 | J29: ='CALCULATION SHEET'!D56 -> 0.092879963 | L29: ='CALCULATION SHEET'!G57 -> 230 | M29: ='CALCULATION SHEET'!H57 -> 190 | N29: ='CALCULATION SHEET'!L57 -> 327 | P29: ='CALCULATION SHEET'!M57 -> 62 | R29: ='CALCULATION SHEET'!Q56 -> 36654.423 | T29: =H29 -> 407
E30: Executive Management | H30: ='CALCULATION SHEET'!C57 -> 420 | J30: ='CALCULATION SHEET'!D57 -> 0.095846645 | L30: ='CALCULATION SHEET'!G58 -> 229 | M30: ='CALCULATION SHEET'!H58 -> 169 | N30: ='CALCULATION SHEET'!L58 -> 316 | P30: ='CALCULATION SHEET'!M58 -> 63 | R30: ='CALCULATION SHEET'!Q57 -> 14416.964 | T30: =H30 -> 420
E31: Legal | H31: ='CALCULATION SHEET'!C58 -> 422 | J31: ='CALCULATION SHEET'!D58 -> 0.096303058 | L31: ='CALCULATION SHEET'!G59 -> 209 | M31: ='CALCULATION SHEET'!H59 -> 176 | N31: ='CALCULATION SHEET'!L59 -> 308 | P31: ='CALCULATION SHEET'!M59 -> 52 | R31: ='CALCULATION SHEET'!Q58 -> 12158.011 | T31: =H31 -> 422

Sheet ATTRITION
D1: ATTRITION ANALYSIS
A6: DASHBOARD
B8: Overview
B10: Headcount
B12: Attrition
B14: Training & ROI
A20: Period: Jan 2024 – May 2026

Sheet TRAINING
D1: TRAINING ANALYSIS
A6: DASHBOARD
B8: Overview
B10: Headcount
B12: Attrition
B14: Training & ROI
A20: Period: Jan 2024 – May 2026

Sheet TRAINING DATA 
A1: Training ID | B1: Program Name | C1: Category | D1: Training Date | E1: Duration (Days) | F1: Employee ID | G1: Department | H1: Job Grade | I1: Cost per Head ($) | J1: Completed | K1: Pre-Training Score | L1: Post-Training Score | M1: Score Improvement | N1: Score Improvement(%)
A2: TRN-3001 | B2: Leadership Development | C2: Leadership | D2: 45651 | E2: 3 | F2: EMP-14282 | G2: Procurement | H2: Grade 3 – Mid-Level | I2: 3500 | J2: Yes | K2: 50.5 | L2: 73.2 | M2: =Table2[[#This Row],[Post-Training Score]]-Table2[[#This Row],[Pre-Training Score]] -> 22.7 | N2: =(Table2[[#This Row],[Score Improvement]]/Table2[[#This Row],[Pre-Training Score]]) -> 0.44950495
A3: TRN-3001 | B3: Leadership Development | C3: Leadership | D3: 45651 | E3: 3 | F3: EMP-14957 | G3: Information Technology | H3: Grade 3 – Mid-Level | I3: 3500 | J3: Yes | K3: 42.3 | L3: 53.8 | M3: =Table2[[#This Row],[Post-Training Score]]-Table2[[#This Row],[Pre-Training Score]] -> 11.5 | N3: =(Table2[[#This Row],[Score Improvement]]/Table2[[#This Row],[Pre-Training Score]]) -> 0.27186761
A4: TRN-3001 | B4: Leadership Development | C4: Leadership | D4: 45651 | E4: 3 | F4: EMP-10101 | G4: Information Technology | H4: Grade 5 – Lead | I4: 3500 | J4: Yes | K4: 66.5 | L4: 85.3 | M4: =Table2[[#This Row],[Post-Training Score]]-Table2[[#This Row],[Pre-Training Score]] -> 18.8 | N4: =(Table2[[#This Row],[Score Improvement]]/Table2[[#This Row],[Pre-Training Score]]) -> 0.28270677
A5: TRN-3001 | B5: Leadership Development | C5: Leadership | D5: 45651 | E5: 3 | F5: EMP-13494 | G5: Procurement | H5: Grade 2 – Junior | I5: 3500 | J5: Yes | K5: 51.8 | L5: 65.2 | M5: =Table2[[#This Row],[Post-Training Score]]-Table2[[#This Row],[Pre-Training Score]] -> 13.4 | N5: =(Table2[[#This Row],[Score Improvement]]/Table2[[#This Row],[Pre-Training Score]]) -> 0.25868726
A6: TRN-3001 | B6: Leadership Development | C6: Leadership | D6: 45651 | E6: 3 | F6: EMP-11989 | G6: Executive Management | H6: Grade 7 – Director | I6: 3500 | J6: Yes | K6: 49.2 | L6: 62.3 | M6: =Table2[[#This Row],[Post-Training Score]]-Table2[[#This Row],[Pre-Training Score]] -> 13.1 | N6: =(Table2[[#This Row],[Score Improvement]]/Table2[[#This Row],[Pre-Training Score]]) -> 0.26626016
A7: TRN-3001 | B7: Leadership Development | C7: Leadership | D7: 45651 | E7: 3 | F7: EMP-12564 | G7: Customer Service | H7: Grade 3 – Mid-Level | I7: 3500 | J7: Yes | K7: 58.9 | L7: 86.4 | M7: =Table2[[#This Row],[Post-Training Score]]-Table2[[#This Row],[Pre-Training Score]] -> 27.5 | N7: =(Table2[[#This Row],[Score Improvement]]/Table2[[#This Row],[Pre-Training Score]]) -> 0.46689304
A8: TRN-3001 | B8: Leadership Development | C8: Leadership | D8: 45651 | E8: 3 | F8: EMP-10424 | G8: Human Resources | H8: Grade 4 – Senior | I8: 3500 | J8: Yes | K8: 40.8 | L8: 71.6 | M8: =Table2[[#This Row],[Post-Training Score]]-Table2[[#This Row],[Pre-Training Score]] -> 30.8 | N8: =(Table2[[#This Row],[Score Improvement]]/Table2[[#This Row],[Pre-Training Score]]) -> 0.75490196
A9: TRN-3001 | B9: Leadership Development | C9: Leadership | D9: 45651 | E9: 3 | F9: EMP-15477 | G9: Procurement | H9: Grade 1 – Entry | I9: 3500 | J9: No | M9: =Table2[[#This Row],[Post-Training Score]]-Table2[[#This Row],[Pre-Training Score]] -> 0 | N9: =(Table2[[#This Row],[Score Improvement]]/Table2[[#This Row],[Pre-Training Score]]) -> #DIV/0!
A10: TRN-3001 | B10: Leadership Development | C10: Leadership | D10: 45651 | E10: 3 | F10: EMP-13374 | G10: Risk & Compliance | H10: Grade 1 – Entry | I10: 3500 | J10: Yes | K10: 60.7 | L10: 83.7 | M10: =Table2[[#This Row],[Post-Training Score]]-Table2[[#This Row],[Pre-Training Score]] -> 23 | N10: =(Table2[[#This Row],[Score Improvement]]/Table2[[#This Row],[Pre-Training Score]]) -> 0.37891269
A11: TRN-3001 | B11: Leadership Development | C11: Leadership | D11: 45651 | E11: 3 | F11: EMP-10910 | G11: Customer Service | H11: Grade 4 – Senior | I11: 3500 | J11: Yes | K11: 42.6 | L11: 55.9 | M11: =Table2[[#This Row],[Post-Training Score]]-Table2[[#This Row],[Pre-Training Score]] -> 13.3 | N11: =(Table2[[#This Row],[Score Improvement]]/Table2[[#This Row],[Pre-Training Score]]) -> 0.31220657
A12: TRN-3001 | B12: Leadership Development | C12: Leadership | D12: 45651 | E12: 3 | F12: EMP-12047 | G12: Risk & Compliance | H12: Grade 2 – Junior | I12: 3500 | J12: Yes | K12: 63.8 | L12: 88 | M12: =Table2[[#This Row],[Post-Training Score]]-Table2[[#This Row],[Pre-Training Score]] -> 24.2 | N12: =(Table2[[#This Row],[Score Improvement]]/Table2[[#This Row],[Pre-Training Score]]) -> 0.37931034
A13: TRN-3001 | B13: Leadership Development | C13: Leadership | D13: 45651 | E13: 3 | F13: EMP-13954 | G13: Human Resources | H13: Grade 4 – Senior | I13: 3500 | J13: Yes | K13: 50.3 | L13: 77.3 | M13: =Table2[[#This Row],[Post-Training Score]]-Table2[[#This Row],[Pre-Training Score]] -> 27 | N13: =(Table2[[#This Row],[Score Improvement]]/Table2[[#This Row],[Pre-Training Score]]) -> 0.53677932
A14: TRN-3001 | B14: Leadership Development | C14: Leadership | D14: 45651 | E14: 3 | F14: EMP-10613 | G14: Human Resources | H14: Grade 3 – Mid-Level | I14: 3500 | J14: Yes | K14: 48 | L14: 59.4 | M14: =Table2[[#This Row],[Post-Training Score]]-Table2[[#This Row],[Pre-Training Score]] -> 11.4 | N14: =(Table2[[#This Row],[Score Improvement]]/Table2[[#This Row],[Pre-Training Score]]) -> 0.2375
A15: TRN-3001 | B15: Leadership Development | C15: Leadership | D15: 45651 | E15: 3 | F15: EMP-14087 | G15: Sales | H15: Grade 2 – Junior | I15: 3500 | J15: Yes | K15: 44.8 | L15: 77.3 | M15: =Table2[[#This Row],[Post-Training Score]]-Table2[[#This Row],[Pre-Training Score]] -> 32.5 | N15: =(Table2[[#This Row],[Score Improvement]]/Table2[[#This Row],[Pre-Training Score]]) -> 0.72544643
A16: TRN-3001 | B16: Leadership Development | C16: Leadership | D16: 45651 | E16: 3 | F16: EMP-14138 | G16: Information Technology | H16: Grade 4 – Senior | I16: 3500 | J16: Yes | K16: 69.1 | L16: 92.6 | M16: =Table2[[#This Row],[Post-Training Score]]-Table2[[#This Row],[Pre-Training Score]] -> 23.5 | N16: =(Table2[[#This Row],[Score Improvement]]/Table2[[#This Row],[Pre-Training Score]]) -> 0.34008683
A17: TRN-3001 | B17: Leadership Development | C17: Leadership | D17: 45651 | E17: 3 | F17: EMP-11877 | G17: Legal | H17: Grade 6 – Manager | I17: 3500 | J17: Yes | K17: 70.8 | L17: 100 | M17: =Table2[[#This Row],[Post-Training Score]]-Table2[[#This Row],[Pre-Training Score]] -> 29.2 | N17: =(Table2[[#This Row],[Score Improvement]]/Table2[[#This Row],[Pre-Training Score]]) -> 0.41242938
A18: TRN-3001 | B18: Leadership Development | C18: Leadership | D18: 45651 | E18: 3 | F18: EMP-13167 | G18: Marketing | H18: Grade 3 – Mid-Level | I18: 3500 | J18: Yes | K18: 66.4 | L18: 77.4 | M18: =Table2[[#This Row],[Post-Training Score]]-Table2[[#This Row],[Pre-Training Score]] -> 11 | N18: =(Table2[[#This Row],[Score Improvement]]/Table2[[#This Row],[Pre-Training Score]]) -> 0.16566265
A19: TRN-3001 | B19: Leadership Development | C19: Leadership | D19: 45651 | E19: 3 | F19: EMP-13736 | G19: Information Technology | H19: Grade 2 – Junior | I19: 3500 | J19: Yes | K19: 69.2 | L19: 86.1 | M19: =Table2[[#This Row],[Post-Training Score]]-Table2[[#This Row],[Pre-Training Score]] -> 16.9 | N19: =(Table2[[#This Row],[Score Improvement]]/Table2[[#This Row],[Pre-Training Score]]) -> 0.24421965
A20: TRN-3001 | B20: Leadership Development | C20: Leadership | D20: 45651 | E20: 3 | F20: EMP-14272 | G20: Risk & Compliance | H20: Grade 6 – Manager | I20: 3500 | J20: Yes | K20: 53.8 | L20: 81.7 | M20: =Table2[[#This Row],[Post-Training Score]]-Table2[[#This Row],[Pre-Training Score]] -> 27.9 | N20: =(Table2[[#This Row],[Score Improvement]]/Table2[[#This Row],[Pre-Training Score]]) -> 0.51858736
A21: TRN-3001 | B21: Leadership Development | C21: Leadership | D21: 45651 | E21: 3 | F21: EMP-10909 | G21: Information Technology | H21: Grade 3 – Mid-Level | I21: 3500 | J21: Yes | K21: 41.4 | L21: 68.3 | M21: =Table2[[#This Row],[Post-Training Score]]-Table2[[#This Row],[Pre-Training Score]] -> 26.9 | N21: =(Table2[[#This Row],[Score Improvement]]/Table2[[#This Row],[Pre-Training Score]]) -> 0.64975845
... A40: TRN-3001 | B40: Leadership Development | C40: Leadership | D40: 45651 | E40: 3 | F40: EMP-14167 | G40: Marketing | H40: Grade 1 – Entry | I40: 3500 | J40: Yes | K40: 68.3 | L40: 96.4 | M40: =Table2[[#This Row],[Post-Training Score]]-Table2[[#This Row],[Pre-Training Score]] -> 28.1 | N40: =(Table2[[#This Row],[Score Improvement]]/Table2[[#This Row],[Pre-Training Score]]) -> 0.4114202
A41: TRN-3001 | B41: Leadership Development | C41: Leadership | D41: 45651 | E41: 3 | F41: EMP-12073 | G41: Human Resources | H41: Grade 3 – Mid-Level | I41: 3500 | J41: No | M41: =Table2[[#This Row],[Post-Training Score]]-Table2[[#This Row],[Pre-Training Score]] -> 0 | N41: =(Table2[[#This Row],[Score Improvement]]/Table2[[#This Row],[Pre-Training Score]]) -> #DIV/0!
A42: TRN-3001 | B42: Leadership Development | C42: Leadership | D42: 45651 | E42: 3 | F42: EMP-10041 | G42: Human Resources | H42: Grade 6 – Manager | I42: 3500 | J42: No | M42: =Table2[[#This Row],[Post-Training Score]]-Table2[[#This Row],[Pre-Training Score]] -> 0 | N42: =(Table2[[#This Row],[Score Improvement]]/Table2[[#This Row],[Pre-Training Score]]) -> #DIV/0!
A43: TRN-3001 | B43: Leadership Development | C43: Leadership | D43: 45651 | E43: 3 | F43: EMP-14089 | G43: Legal | H43: Grade 3 – Mid-Level | I43: 3500 | J43: Yes | K43: 52.7 | L43: 77.2 | M43: =Table2[[#This Row],[Post-Training Score]]-Table2[[#This Row],[Pre-Training Score]] -> 24.5 | N43: =(Table2[[#This Row],[Score Improvement]]/Table2[[#This Row],[Pre-Training Score]]) -> 0.46489564
A44: TRN-3001 | B44: Leadership Development | C44: Leadership | D44: 45651 | E44: 3 | F44: EMP-12071 | G44: Sales | H44: Grade 3 – Mid-Level | I44: 3500 | J44: Yes | K44: 47.2 | L44: 63.9 | M44: =Table2[[#This Row],[Post-Training Score]]-Table2[[#This Row],[Pre-Training Score]] -> 16.7 | N44: =(Table2[[#This Row],[Score Improvement]]/Table2[[#This Row],[Pre-Training Score]]) -> 0.35381356
A45: TRN-3001 | B45: Leadership Development | C45: Leadership | D45: 45651 | E45: 3 | F45: EMP-13371 | G45: Human Resources | H45: Grade 3 – Mid-Level | I45: 3500 | J45: Yes | K45: 73.5 | L45: 79 | M45: =Table2[[#This Row],[Post-Training Score]]-Table2[[#This Row],[Pre-Training Score]] -> 5.5 | N45: =(Table2[[#This Row],[Score Improvement]]/Table2[[#This Row],[Pre-Training Score]]) -> 0.074829932
A46: TRN-3001 | B46: Leadership Development | C46: Leadership | D46: 45651 | E46: 3 | F46: EMP-12929 | G46: Procurement | H46: Grade 1 – Entry | I46: 3500 | J46: Yes | K46: 42.8 | L46: 55.1 | M46: =Table2[[#This Row],[Post-Training Score]]-Table2[[#This Row],[Pre-Training Score]] -> 12.3 | N46: =(Table2[[#This Row],[Score Improvement]]/Table2[[#This Row],[Pre-Training Score]]) -> 0.28738318
A47: TRN-3001 | B47: Leadership Development | C47: Leadership | D47: 45651 | E47: 3 | F47: EMP-15407 | G47: Customer Service | H47: Grade 1 – Entry | I47: 3500 | J47: Yes | K47: 42.4 | L47: 53.1 | M47: =Table2[[#This Row],[Post-Training Score]]-Table2[[#This Row],[Pre-Training Score]] -> 10.7 | N47: =(Table2[[#This Row],[Score Improvement]]/Table2[[#This Row],[Pre-Training Score]]) -> 0.25235849
A48: TRN-3001 | B48: Leadership Development | C48: Leadership | D48: 45651 | E48: 3 | F48: EMP-13583 | G48: Finance | H48: Grade 4 – Senior | I48: 3500 | J48: Yes | K48: 54 | L48: 63.8 | M48: =Table2[[#This Row],[Post-Training Score]]-Table2[[#This Row],[Pre-Training Score]] -> 9.8 | N48: =(Table2[[#This Row],[Score Improvement]]/Table2[[#This Row],[Pre-Training Score]]) -> 0.18148148
A49: TRN-3001 | B49: Leadership Development | C49: Leadership | D49: 45651 | E49: 3 | F49: EMP-11994 | G49: Executive Management | H49: Grade 7 – Director | I49: 3500 | J49: Yes | K49: 55.4 | L49: 90.3 | M49: =Table2[[#This Row],[Post-Training Score]]-Table2[[#This Row],[Pre-Training Score]] -> 34.9 | N49: =(Table2[[#This Row],[Score Improvement]]/Table2[[#This Row],[Pre-Training Score]]) -> 0.6299639
A50: TRN-3001 | B50: Leadership Development | C50: Leadership | D50: 45651 | E50: 3 | F50: EMP-14296 | G50: Procurement | H50: Grade 3 – Mid-Level | I50: 3500 | J50: Yes | K50: 43 | L50: 65.8 | M50: =Table2[[#This Row],[Post-Training Score]]-Table2[[#This Row],[Pre-Training Score]] -> 22.8 | N50: =(Table2[[#This Row],[Score Improvement]]/Table2[[#This Row],[Pre-Training Score]]) -> 0.53023256
A51: TRN-3001 | B51: Leadership Development | C51: Leadership | D51: 45651 | E51: 3 | F51: EMP-10924 | G51: Risk & Compliance | H51: Grade 6 – Manager | I51: 3500 | J51: Yes | K51: 52 | L51: 63.2 | M51: =Table2[[#This Row],[Post-Training Score]]-Table2[[#This Row],[Pre-Training Score]] -> 11.2 | N51: =(Table2[[#This Row],[Score Improvement]]/Table2[[#This Row],[Pre-Training Score]]) -> 0.21538462
A52: TRN-3001 | B52: Leadership Development | C52: Leadership | D52: 45651 | E52: 3 | F52: EMP-10142 | G52: Customer Service | H52: Grade 1 – Entry | I52: 3500 | J52: Yes | K52: 73.9 | L52: 80.2 | M52: =Table2[[#This Row],[Post-Training Score]]-Table2[[#This Row],[Pre-Training Score]] -> 6.3 | N52: =(Table2[[#This Row],[Score Improvement]]/Table2[[#This Row],[Pre-Training Score]]) -> 0.085250338
A53: TRN-3001 | B53: Leadership Development | C53: Leadership | D53: 45651 | E53: 3 | F53: EMP-12995 | G53: Executive Management | H53: Grade 5 – Lead | I53: 3500 | J53: Yes | K53: 65.2 | L53: 80.5 | M53: =Table2[[#This Row],[Post-Training Score]]-Table2[[#This Row],[Pre-Training Score]] -> 15.3 | N53: =(Table2[[#This Row],[Score Improvement]]/Table2[[#This Row],[Pre-Training Score]]) -> 0.23466258
A54: TRN-3001 | B54: Leadership Development | C54: Leadership | D54: 45651 | E54: 3 | F54: EMP-15290 | G54: Sales | H54: Grade 1 – Entry | I54: 3500 | J54: Yes | K54: 40.3 | L54: 49.4 | M54: =Table2[[#This Row],[Post-Training Score]]-Table2[[#This Row],[Pre-Training Score]] -> 9.1 | N54: =(Table2[[#This Row],[Score Improvement]]/Table2[[#This Row],[Pre-Training Score]]) -> 0.22580645
... A61: TRN-3001 | B61: Leadership Development | C61: Leadership | D61: 45651 | E61: 3 | F61: EMP-14970 | G61: Human Resources | H61: Grade 2 – Junior | I61: 3500 | J61: Yes | K61: 63.8 | L61: 76.7 | M61: =Table2[[#This Row],[Post-Training Score]]-Table2[[#This Row],[Pre-Training Score]] -> 12.9 | N61: =(Table2[[#This Row],[Score Improvement]]/Table2[[#This Row],[Pre-Training Score]]) -> 0.20219436
A62: TRN-3001 | B62: Leadership Development | C62: Leadership | D62: 45651 | E62: 3 | F62: EMP-13688 | G62: Finance | H62: Grade 4 – Senior | I62: 3500 | J62: No | M62: =Table2[[#This Row],[Post-Training Score]]-Table2[[#This Row],[Pre-Training Score]] -> 0 | N62: =(Table2[[#This Row],[Score Improvement]]/Table2[[#This Row],[Pre-Training Score]]) -> #DIV/0!
A63: TRN-3001 | B63: Leadership Development | C63: Leadership | D63: 45651 | E63: 3 | F63: EMP-15447 | G63: Procurement | H63: Grade 3 – Mid-Level | I63: 3500 | J63: Yes | K63: 54 | L63: 62.9 | M63: =Table2[[#This Row],[Post-Training Score]]-Table2[[#This Row],[Pre-Training Score]] -> 8.9 | N63: =(Table2[[#This Row],[Score Improvement]]/Table2[[#This Row],[Pre-Training Score]]) -> 0.16481481
A64: TRN-3001 | B64: Leadership Development | C64: Leadership | D64: 45651 | E64: 3 | F64: EMP-12611 | G64: Marketing | H64: Grade 2 – Junior | I64: 3500 | J64: Yes | K64: 74.7 | L64: 100 | M64: =Table2[[#This Row],[Post-Training Score]]-Table2[[#This Row],[Pre-Training Score]] -> 25.3 | N64: =(Table2[[#This Row],[Score Improvement]]/Table2[[#This Row],[Pre-Training Score]]) -> 0.33868809
...

Sheet RECRUITMENT TRACKER
A1: Requisition ID | B1: Department | C1: Branch | D1: Job Grade | E1: Date Posted | F1: Date Closed | G1: Time to Fill (Days) | H1: Applications Received | I1: Shortlisted | J1: Interviewed | K1: Hired | L1: Hire Source | M1: Hired Employee ID | N1: Recruitment Cost ($) | O1: Status
A2: REQ-2025-1001 | B2: Sales | C2: Head Office | D2: Grade 2 – Junior | E2: 45952 | F2: 46033 | G2: 81 | H2: 91 | I2: 22 | J2: 14 | K2: 1 | L2: Job Portal | M2: EMP-10002 | N2: 548 | O2: Closed – Filled
A3: REQ-2025-1002 | B3: Information Technology | C3: Head Office | D3: Grade 5 – Lead | E3: 45875 | F3: 45960 | G3: 85 | H3: 82 | I3: 12 | J3: 7 | K3: 1 | L3: LinkedIn | M3: EMP-10003 | N3: 710 | O3: Closed – Filled
A4: REQ-2024-1003 | B4: Information Technology | C4: East Region | D4: Grade 5 – Lead | E4: 45418 | F4: 45465 | G4: 47 | H4: 36 | I4: 18 | J4: 14 | K4: 1 | L4: Job Portal | M4: EMP-10005 | N4: 456 | O4: Closed – Filled
A5: REQ-2024-1004 | B5: Customer Service | C5: South Region | D5: Grade 3 – Mid-Level | E5: 45604 | F5: 45662 | G5: 58 | H5: 21 | I5: 5 | J5: 5 | K5: 1 | L5: Employee Referral | M5: EMP-10013 | N5: 58 | O5: Closed – Filled
A6: REQ-2025-1005 | B6: Information Technology | C6: North Region | D6: Grade 4 – Senior | E6: 45390 | F6: 45439 | G6: 49 | H6: 76 | I6: 29 | J6: 10 | K6: 1 | L6: Job Portal | M6: EMP-10019 | N6: 405 | O6: Closed – Filled
A7: REQ-2025-1006 | B7: Human Resources | C7: South Region | D7: Grade 4 – Senior | E7: 46061 | F7: 46087 | G7: 26 | H7: 63 | I7: 22 | J7: 7 | K7: 1 | L7: Job Portal | M7: EMP-10020 | N7: 348 | O7: Closed – Filled
A8: REQ-2025-1007 | B8: Risk & Compliance | C8: Head Office | D8: Grade 3 – Mid-Level | E8: 45337 | F8: 45377 | G8: 40 | H8: 101 | I8: 6 | J8: 6 | K8: 1 | L8: Employee Referral | M8: EMP-10024 | N8: 292 | O8: Closed – Filled
